Workbook

Sheet คำนวณเกษียณ
B1: ⚡ โปรแกรมคำนวณแผนเกษียณ พนักงาน กฟภ.
B2: กรอกข้อมูลของคุณในช่องสีเหลือง (ตัวเลขสีน้ำเงิน) ผลลัพธ์จะคำนวณอัตโนมัติในส่วน "ผลการคำนวณ" ด้านล่าง
B4: 🟨 สีเหลือง / ตัวเลขสีน้ำเงิน = ช่องที่ต้องกรอกข้อมูลของท่าน ⬛ ตัวเลขสีดำ = คำนวณอัตโนมัติ ห้ามแก้ไข
B6: หมวด 1 : ข้อมูลเบื้องต้น
B7: อายุปัจจุบัน | C7: 40 | D7: ปี
B8: อายุที่ต้องการเกษียณ | C8: 60 | D8: ปี
B9: อายุขัยโดยประมาณ | C9: 85 | D9: ปี
B10: เงินเดือนปัจจุบัน | C10: 30160 | D10: บาท/เดือน
B11: อัตราขึ้นเงินเดือนเฉลี่ยต่อปี | C11: 0.07 | D11: % ต่อปี
B13: หมวด 2 : เงินที่ต้องใช้ตอนเกษียณ
B14: เงินที่ต้องการใช้หลังเกษียณ (มูลค่าปัจจุบัน) | C14: 25000 | D14: บาท/เดือน
B15: อัตราเงินเฟ้อเฉลี่ยต่อปี | C15: 0.03 | D15: % ต่อปี
B16: อัตราผลตอบแทนเฉลี่ยหลังเกษียณต่อปี | C16: 0.05 | D16: % ต่อปี
B17: เงินที่ต้องการใช้หลังเกษียณ (ปรับเงินเฟ้อแล้ว) | C17: =C14*(1+C15)^(C8-C7) -> 45152.781 | D17: บาท/เดือน
B19: หมวด 3 : การออม
B20: เงินที่ออมได้ต่อเดือน (นอกเหนือ กสช.+หุ้นสหกรณ์) | C20: 0 | D20: บาท/เดือน
B21: เงินออมตั้งต้นที่มีอยู่ในปัจจุบัน | C21: 0 | D21: บาท
B22: อัตราผลตอบแทนเฉลี่ยก่อนเกษียณต่อปี | C22: 0.05 | D22: % ต่อปี
B23: สะสมหุ้นสหกรณ์ฯ ต่อเดือน | C23: 1000 | D23: บาท/เดือน
B24: มูลค่าหุ้นสหกรณ์ปัจจุบัน | C24: 150000 | D24: บาท
B26: หมวด 4 : กองทุนสำรองเลี้ยงชีพ (กสช.)
B27: อัตราเงินสะสม (ส่วนของพนักงาน) | C27: 0.07 | D27: % ของเงินเดือน
B28: อัตราเงินสมทบ (ส่วนของนายจ้าง) | C28: 0.1 | D28: % ของเงินเดือน
B29: อัตราผลตอบแทน กสช. เฉลี่ยต่อปี | C29: 0.07 | D29: % ต่อปี
B30: เงินสะสม สะสมล่าสุด (ส่วนพนักงาน) | C30: 26519.92 | D30: บาท
B31: เงินสมทบ สะสมล่าสุด (ส่วนนายจ้าง) | C31: 36487.8 | D31: บาท
B32: ผลประโยชน์เงินสะสม สะสมล่าสุด | C32: 1900.05 | D32: บาท
B33: ผลประโยชน์เงินสมทบ สะสมล่าสุด | C33: 2544.02 | D33: บาท
B35: ผลการคำนวณ
B36: จำนวนปีจนถึงเกษียณ (n1) | C36: =C8-C7 -> 20 | D36: ปี
B37: จำนวนปีหลังเกษียณ (n2) | C37: =C9-C8 -> 25 | D37: ปี
B38: ผลตอบแทนที่แท้จริงหลังเกษียณ ต่อปี (ค่าช่วยคำนวณ) | C38: =(1+C16)/(1+C15)-1 -> 0.019417476
B39: ผลตอบแทนที่แท้จริง ต่อเดือน (ค่าช่วยคำนวณ) | C39: =(1+C38)^(1/12)-1 -> 0.0016038984
B40: จำนวนเดือนหลังเกษียณ (ค่าช่วยคำนวณ) | C40: =C37*12 -> 300 | D40: เดือน
B41: เงินที่ต้องมี ณ วันเกษียณ (รวมทั้งหมด) | C41: =IF(C40<=0,0,IF(ABS(C39)<0.0000001,C17*C40,C17*(1-(1+C39)^(-C40))/C39*(1+C39))) -> 10762858 | D41: บาท
B42: มูลค่า กสช. ณ วันเกษียณ | C42: =INDEX(ตารางจำลอง!C2:C67,C36+1) -> 4852290 | D42: บาท
B43: มูลค่าเงินออมอื่นๆ ณ วันเกษียณ | C43: =INDEX(ตารางจำลอง!D2:D67,C36+1) -> 0 | D43: บาท
B44: มูลค่าหุ้นสหกรณ์ฯ ณ วันเกษียณ (ไม่คิดผลตอบแทน) | C44: =C24+C23*C36*12 -> 390000 | D44: บาท
B45: รวมเงินที่คาดว่าจะมีทั้งหมด | C45: =C42+C43+C44 -> 5242290 | D45: บาท
B46: ส่วนต่าง (เกิน / ขาด) | C46: =C45-C41 -> -5520568.2 | D46: บาท
...

Sheet ตารางจำลอง
A1: อายุ | B1: เงินเดือน (บาท/เดือน) | C1: ยอดสะสม กสช. (บาท) | D1: ยอดสะสม เงินออมอื่นๆ (บาท) | F1: ตารางนี้จำลองการเติบโตของ กสช. และเงินออมส่วนตัวปีต่อปี ตั้งแต่อายุปัจจุบันจนถึงอายุเกษียณ (ใช้โดยสูตร INDEX ในแท็บคำนวณเกษียณ ไม่ต้องแก้ไขตารางนี้)
A2: =คำนวณเกษียณ!C7 -> 40 | B2: =คำนวณเกษียณ!C10 -> 30160 | C2: =คำนวณเกษียณ!C30+คำนวณเกษียณ!C31+คำนวณเกษียณ!C32+คำนวณเกษียณ!C33 -> 67451.79 | D2: =คำนวณเกษียณ!C21 -> 0 | F2: อัตราผลตอบแทน กสช. ต่อเดือน | G2: =(1+คำนวณเกษียณ!C29)^(1/12)-1 -> 0.0056541454
A3: =A2+1 -> 41 | B3: =IF(A2>=คำนวณเกษียณ!$C$8,B2,B2*(1+คำนวณเกษียณ!$C$11)) -> 32271.2 | C3: =IF(A2>=คำนวณเกษียณ!$C$8,C2,IFERROR(C2*(1+$G$2)^12+B2*$G$4*((1+$G$2)^12-1)/$G$2,C2+B2*$G$4*12)) -> 135649.67 | D3: =IF(A2>=คำนวณเกษียณ!$C$8,D2,IFERROR(D2*(1+$G$3)^12+คำนวณเกษียณ!$C$20*((1+$G$3)^12-1)/$G$3,D2+คำนวณเกษียณ!$C$20*12)) -> 0 | F3: อัตราผลตอบแทนเงินออมอื่น ต่อเดือน | G3: =(1+คำนวณเกษียณ!C22)^(1/12)-1 -> 0.0040741238
A4: =A3+1 -> 42 | B4: =IF(A3>=คำนวณเกษียณ!$C$8,B3,B3*(1+คำนวณเกษียณ!$C$11)) -> 34530.184 | C4: =IF(A3>=คำนวณเกษียณ!$C$8,C3,IFERROR(C3*(1+$G$2)^12+B3*$G$4*((1+$G$2)^12-1)/$G$2,C3+B3*$G$4*12)) -> 213064.75 | D4: =IF(A3>=คำนวณเกษียณ!$C$8,D3,IFERROR(D3*(1+$G$3)^12+คำนวณเกษียณ!$C$20*((1+$G$3)^12-1)/$G$3,D3+คำนวณเกษียณ!$C$20*12)) -> 0 | F4: อัตราเงินสะสม+เงินสมทบ รวม | G4: =คำนวณเกษียณ!C27+คำนวณเกษียณ!C28 -> 0.17
A5: =A4+1 -> 43 | B5: =IF(A4>=คำนวณเกษียณ!$C$8,B4,B4*(1+คำนวณเกษียณ!$C$11)) -> 36947.297 | C5: =IF(A4>=คำนวณเกษียณ!$C$8,C4,IFERROR(C4*(1+$G$2)^12+B4*$G$4*((1+$G$2)^12-1)/$G$2,C4+B4*$G$4*12)) -> 300653.25 | D5: =IF(A4>=คำนวณเกษียณ!$C$8,D4,IFERROR(D4*(1+$G$3)^12+คำนวณเกษียณ!$C$20*((1+$G$3)^12-1)/$G$3,D4+คำนวณเกษียณ!$C$20*12)) -> 0
A6: =A5+1 -> 44 | B6: =IF(A5>=คำนวณเกษียณ!$C$8,B5,B5*(1+คำนวณเกษียณ!$C$11)) -> 39533.608 | C6: =IF(A5>=คำนวณเกษียณ!$C$8,C5,IFERROR(C5*(1+$G$2)^12+B5*$G$4*((1+$G$2)^12-1)/$G$2,C5+B5*$G$4*12)) -> 399460.13 | D6: =IF(A5>=คำนวณเกษียณ!$C$8,D5,IFERROR(D5*(1+$G$3)^12+คำนวณเกษียณ!$C$20*((1+$G$3)^12-1)/$G$3,D5+คำนวณเกษียณ!$C$20*12)) -> 0
A7: =A6+1 -> 45 | B7: =IF(A6>=คำนวณเกษียณ!$C$8,B6,B6*(1+คำนวณเกษียณ!$C$11)) -> 42300.96 | C7: =IF(A6>=คำนวณเกษียณ!$C$8,C6,IFERROR(C6*(1+$G$2)^12+B6*$G$4*((1+$G$2)^12-1)/$G$2,C6+B6*$G$4*12)) -> 510626.76 | D7: =IF(A6>=คำนวณเกษียณ!$C$8,D6,IFERROR(D6*(1+$G$3)^12+คำนวณเกษียณ!$C$20*((1+$G$3)^12-1)/$G$3,D6+คำนวณเกษียณ!$C$20*12)) -> 0
A8: =A7+1 -> 46 | B8: =IF(A7>=คำนวณเกษียณ!$C$8,B7,B7*(1+คำนวณเกษียณ!$C$11)) -> 45262.027 | C8: =IF(A7>=คำนวณเกษียณ!$C$8,C7,IFERROR(C7*(1+$G$2)^12+B7*$G$4*((1+$G$2)^12-1)/$G$2,C7+B7*$G$4*12)) -> 635399.37 | D8: =IF(A7>=คำนวณเกษียณ!$C$8,D7,IFERROR(D7*(1+$G$3)^12+คำนวณเกษียณ!$C$20*((1+$G$3)^12-1)/$G$3,D7+คำนวณเกษียณ!$C$20*12)) -> 0
A9: =A8+1 -> 47 | B9: =IF(A8>=คำนวณเกษียณ!$C$8,B8,B8*(1+คำนวณเกษียณ!$C$11)) -> 48430.369 | C9: =IF(A8>=คำนวณเกษียณ!$C$8,C8,IFERROR(C8*(1+$G$2)^12+B8*$G$4*((1+$G$2)^12-1)/$G$2,C8+B8*$G$4*12)) -> 775138.08 | D9: =IF(A8>=คำนวณเกษียณ!$C$8,D8,IFERROR(D8*(1+$G$3)^12+คำนวณเกษียณ!$C$20*((1+$G$3)^12-1)/$G$3,D8+คำนวณเกษียณ!$C$20*12)) -> 0
A10: =A9+1 -> 48 | B10: =IF(A9>=คำนวณเกษียณ!$C$8,B9,B9*(1+คำนวณเกษียณ!$C$11)) -> 51820.495 | C10: =IF(A9>=คำนวณเกษียณ!$C$8,C9,IFERROR(C9*(1+$G$2)^12+B9*$G$4*((1+$G$2)^12-1)/$G$2,C9+B9*$G$4*12)) -> 931326.75 | D10: =IF(A9>=คำนวณเกษียณ!$C$8,D9,IFERROR(D9*(1+$G$3)^12+คำนวณเกษียณ!$C$20*((1+$G$3)^12-1)/$G$3,D9+คำนวณเกษียณ!$C$20*12)) -> 0
A11: =A10+1 -> 49 | B11: =IF(A10>=คำนวณเกษียณ!$C$8,B10,B10*(1+คำนวณเกษียณ!$C$11)) -> 55447.93 | C11: =IF(A10>=คำนวณเกษียณ!$C$8,C10,IFERROR(C10*(1+$G$2)^12+B10*$G$4*((1+$G$2)^12-1)/$G$2,C10+B10*$G$4*12)) -> 1105583.7 | D11: =IF(A10>=คำนวณเกษียณ!$C$8,D10,IFERROR(D10*(1+$G$3)^12+คำนวณเกษียณ!$C$20*((1+$G$3)^12-1)/$G$3,D10+คำนวณเกษียณ!$C$20*12)) -> 0
A12: =A11+1 -> 50 | B12: =IF(A11>=คำนวณเกษียณ!$C$8,B11,B11*(1+คำนวณเกษียณ!$C$11)) -> 59329.285 | C12: =IF(A11>=คำนวณเกษียณ!$C$8,C11,IFERROR(C11*(1+$G$2)^12+B11*$G$4*((1+$G$2)^12-1)/$G$2,C11+B11*$G$4*12)) -> 1299673 | D12: =IF(A11>=คำนวณเกษียณ!$C$8,D11,IFERROR(D11*(1+$G$3)^12+คำนวณเกษียณ!$C$20*((1+$G$3)^12-1)/$G$3,D11+คำนวณเกษียณ!$C$20*12)) -> 0
A13: =A12+1 -> 51 | B13: =IF(A12>=คำนวณเกษียณ!$C$8,B12,B12*(1+คำนวณเกษียณ!$C$11)) -> 63482.335 | C13: =IF(A12>=คำนวณเกษียณ!$C$8,C12,IFERROR(C12*(1+$G$2)^12+B12*$G$4*((1+$G$2)^12-1)/$G$2,C12+B12*$G$4*12)) -> 1515517.5 | D13: =IF(A12>=คำนวณเกษียณ!$C$8,D12,IFERROR(D12*(1+$G$3)^12+คำนวณเกษียณ!$C$20*((1+$G$3)^12-1)/$G$3,D12+คำนวณเกษียณ!$C$20*12)) -> 0
A14: =A13+1 -> 52 | B14: =IF(A13>=คำนวณเกษียณ!$C$8,B13,B13*(1+คำนวณเกษียณ!$C$11)) -> 67926.098 | C14: =IF(A13>=คำนวณเกษียณ!$C$8,C13,IFERROR(C13*(1+$G$2)^12+B13*$G$4*((1+$G$2)^12-1)/$G$2,C13+B13*$G$4*12)) -> 1755211.9 | D14: =IF(A13>=คำนวณเกษียณ!$C$8,D13,IFERROR(D13*(1+$G$3)^12+คำนวณเกษียณ!$C$20*((1+$G$3)^12-1)/$G$3,D13+คำนวณเกษียณ!$C$20*12)) -> 0
A15: =A14+1 -> 53 | B15: =IF(A14>=คำนวณเกษียณ!$C$8,B14,B14*(1+คำนวณเกษียณ!$C$11)) -> 72680.925 | C15: =IF(A14>=คำนวณเกษียณ!$C$8,C14,IFERROR(C14*(1+$G$2)^12+B14*$G$4*((1+$G$2)^12-1)/$G$2,C14+B14*$G$4*12)) -> 2021037.4 | D15: =IF(A14>=คำนวณเกษียณ!$C$8,D14,IFERROR(D14*(1+$G$3)^12+คำนวณเกษียณ!$C$20*((1+$G$3)^12-1)/$G$3,D14+คำนวณเกษียณ!$C$20*12)) -> 0
A16: =A15+1 -> 54 | B16: =IF(A15>=คำนวณเกษียณ!$C$8,B15,B15*(1+คำนวณเกษียณ!$C$11)) -> 77768.59 | C16: =IF(A15>=คำนวณเกษียณ!$C$8,C15,IFERROR(C15*(1+$G$2)^12+B15*$G$4*((1+$G$2)^12-1)/$G$2,C15+B15*$G$4*12)) -> 2315478 | D16: =IF(A15>=คำนวณเกษียณ!$C$8,D15,IFERROR(D15*(1+$G$3)^12+คำนวณเกษียณ!$C$20*((1+$G$3)^12-1)/$G$3,D15+คำนวณเกษียณ!$C$20*12)) -> 0
... A67: =A66+1 -> 105 | B67: =IF(A66>=คำนวณเกษียณ!$C$8,B66,B66*(1+คำนวณเกษียณ!$C$11)) -> 116709.68 | C67: =IF(A66>=คำนวณเกษียณ!$C$8,C66,IFERROR(C66*(1+$G$2)^12+B66*$G$4*((1+$G$2)^12-1)/$G$2,C66+B66*$G$4*12)) -> 4852290 | D67: =IF(A66>=คำนวณเกษียณ!$C$8,D66,IFERROR(D66*(1+$G$3)^12+คำนวณเกษียณ!$C$20*((1+$G$3)^12-1)/$G$3,D66+คำนวณเกษียณ!$C$20*12)) -> 0
